Workbook

Sheet Full 1
B2: PROJECT TITLE | C2: Analysis of the effect of PMM2 variants on PMM2-CDG | I2: COMPANY NAME | K2: UPC
B3: PROJECT MEMBERS | C3: Adriana Dotsenko, Dàlia Jordan, Salomé Murillo, Elsa Rosado i Noah Quixal | I3: DATE | K3: 46303
A5: ID | B5: TASK TITLE | C5: TASK OWNER | D5: PLANNED START DATE | E5: PLANNED END DATE | F5: REAL START DATE | G5: REAL END DATE | H5: DURATION (working days) | I5: STATUS OF THE TASK | J5: W40 | L5: W41 | Q5: W42 | U5: W43 | Z5: W44 | AE5: W45 | AI5: OUTPUT / ACCOMPLISHED WHEN
J6: 01/10 T | K6: 02/10 F | L6: 05/10 M | M6: 06/10 T | N6: 07/10 W | O6: 08/10 T | P6: 09/10 F | Q6: 13/10 T | R6: 14/10 W | S6: 15/10 T | T6: 16/10 F | U6: 19/10 M | V6: 20/10 T | W6: 21/10 W | X6: 22/10 T | Y6: 23/10 F | Z6: 26/10 M | AA6: 27/10 T | AB6: 28/10 W | AC6: 29/10 T | AD6: 30/10 F | AE6: 02/11 M | AF6: 03/11 T | AG6: 04/11 W | AH6: 05/11 T
A7: WP1 | B7: Planning and setup | D7: 46282 | E7: 46304 | H7: =NETWORKDAYS(D7,E7,Holidays!$A$2:$A$1000)
A8: 1.1 | B8: Create the GitHub repository | C8: Dàlia + Salomé | D8: 46282 | E8: 46282 | F8: 46282 | G8: 46282 | H8: =NETWORKDAYS(D8,E8,Holidays!$A$2:$A$1000) | I8: Completed | AI8: Output: Repository with folders, README and .gitignore (before grid: 17/09 is earlier than the 01/10 grid start)
A9: 1.2 | B9: Kick-off meeting | C9: All | D9: 46296 | E9: 46296 | F9: 46296 | G9: 46296 | H9: =NETWORKDAYS(D9,E9,Holidays!$A$2:$A$1000) | I9: Completed | AI9: Output: Organisation and brainstorming
A10: 1.3 | B10: Build the Gantt chart | C10: Dàlia + Noah | D10: 46296 | E10: 46297 | F10: 46296 | G10: 46297 | H10: =NETWORKDAYS(D10,E10,Holidays!$A$2:$A$1000) | I10: Completed | AI10: Output: Complete Gantt chart
A11: 1.4 | B11: Define objectives and team | C11: Adriana | D11: 46297 | E11: 46300 | F11: 46297 | G11: 46300 | H11: =NETWORKDAYS(D11,E11,Holidays!$A$2:$A$1000) | I11: Completed | AI11: Output: Objectives, roles and background written in the README
A12: 1.5 | B12: Risk analysis | C12: Elsa | D12: 46297 | E12: 46300 | F12: 46300 | G12: 46300 | H12: =NETWORKDAYS(D12,E12,Holidays!$A$2:$A$1000) | I12: Completed | AI12: Output: Risk matrix and risk statements
A13: 1.6 | B13: Status tracking document / upload the Gantt to Git | C13: Dàlia + Noah | D13: 46303 | E13: 46304 | F13: 46303 | H13: =NETWORKDAYS(D13,E13,Holidays!$A$2:$A$1000) | I13: In progress | AI13: Output: Table in status/
A14: 1.7 | B14: Review and submission | C14: Dàlia | D14: 46303 | E14: 46304 | H14: =NETWORKDAYS(D14,E14,Holidays!$A$2:$A$1000) | I14: Pending | AI14: Output: Upload to Moodle and update the Gantt
A15: WP2 | B15: Information gathering | D15: 46296 | E15: 46317 | H15: =NETWORKDAYS(D15,E15,Holidays!$A$2:$A$1000)
A16: 2.1 | B16: Search for reviews | C16: Salomé | D16: 46296 | E16: 46300 | F16: 46297 | G16: 46301 | H16: =NETWORKDAYS(D16,E16,Holidays!$A$2:$A$1000) | I16: Completed | AI16: Output: At least 3 reviews
A17: 2.2 | B17: Search for original papers on the mechanism | C17: Salomé | D17: 46296 | E17: 46301 | F17: 46300 | G17: 46301 | H17: =NETWORKDAYS(D17,E17,Holidays!$A$2:$A$1000) | I17: Completed | AI17: Output: At least 5 papers
A18: 2.3 | B18: OMIM: gene-disease relationship | C18: Adriana | D18: 46301 | E18: 46308 | H18: =NETWORKDAYS(D18,E18,Holidays!$A$2:$A$1000) | I18: Pending | AI18: Output: Notes on the gene and the phenotype
A19: 2.4 | B19: UniProt and choice of 2 species | C19: Adriana | D19: 46301 | E19: 46308 | H19: =NETWORKDAYS(D19,E19,Holidays!$A$2:$A$1000) | I19: Pending | AI19: Output: Protein entry and justification of the species
A20: 2.5 | B20: InterPro: domains | C20: Elsa | D20: 46301 | E20: 46308 | H20: =NETWORKDAYS(D20,E20,Holidays!$A$2:$A$1000) | I20: Pending | AI20: Output: List of domains
A21: 2.6 | B21: PDB: healthy and variant structure | C21: Elsa | D21: 46301 | E21: 46308 | H21: =NETWORKDAYS(D21,E21,Holidays!$A$2:$A$1000) | I21: Pending | AI21: Output: Selected PDB IDs
A22: 2.7 | B22: Reference management | C22: Salomé | D22: 46296 | E22: 46317 | F22: 46296 | H22: =NETWORKDAYS(D22,E22,Holidays!$A$2:$A$1000) | I22: In progress | AI22: Output: List in BMC format
A23: WP3 | B23: Bioinformatic analysis | D23: 46308 | E23: 46317 | H23: =NETWORKDAYS(D23,E23,Holidays!$A$2:$A$1000)
A24: 3.1 | B24: Retrieve FASTA sequences (reference, variant and orthologs) | C24: Dàlia | D24: 46308 | E24: 46310 | H24: =NETWORKDAYS(D24,E24,Holidays!$A$2:$A$1000) | I24: Backlog | AI24: Output: FASTA files
A25: 3.2 | B25: Alignments and conservation | C25: Dàlia | D25: 46310 | E25: 46314 | H25: =NETWORKDAYS(D25,E25,Holidays!$A$2:$A$1000) | I25: Backlog | AI25: Output: Alignment and conservation table
A26: 3.3 | B26: Structural comparison: healthy vs variant | C26: Noah | D26: 46308 | E26: 46314 | H26: =NETWORKDAYS(D26,E26,Holidays!$A$2:$A$1000) | I26: Backlog | AI26: Output: Images and notes
A27: 3.4 | B27: Figures | C27: Dàlia + Noah | D27: 46315 | E27: 46317 | H27: =NETWORKDAYS(D27,E27,Holidays!$A$2:$A$1000) | I27: Backlog | AI27: Output: Figures in figures/
A28: 3.5 | B28: Evolutionary and homolog interpretation | C28: Noah | D28: 46308 | E28: 46314 | H28: =NETWORKDAYS(D28,E28,Holidays!$A$2:$A$1000) | I28: Backlog | AI28: Output: Interpretation notes
A29: 3.6 | B29: Limitations of each analysis | C29: Adriana | D29: 46315 | E29: 46317 | H29: =NETWORKDAYS(D29,E29,Holidays!$A$2:$A$1000) | I29: Backlog | AI29: Output: Limitations summary (to be integrated into the Discussion section)
A30: WP4 | B30: Report | D30: 46311 | E30: 46321 | H30: =NETWORKDAYS(D30,E30,Holidays!$A$2:$A$1000)
A31: 4.1 | B31: Cross-explanation session | C31: All | D31: 46315 | E31: 46315 | H31: =NETWORKDAYS(D31,E31,Holidays!$A$2:$A$1000) | I31: Backlog
A32: 4.2 | B32: Report outline | C32: Salomé | D32: 46311 | E32: 46311 | H32: =NETWORKDAYS(D32,E32,Holidays!$A$2:$A$1000) | I32: Backlog | AI32: Output: Report outline (.md file with the BMC sections)
A33: 4.3 | B33: Introduction | C33: Salomé | D33: 46314 | E33: 46317 | H33: =NETWORKDAYS(D33,E33,Holidays!$A$2:$A$1000) | I33: Backlog
A34: 4.4 | B34: Methods | C34: Noah | D34: 46315 | E34: 46317 | H34: =NETWORKDAYS(D34,E34,Holidays!$A$2:$A$1000) | I34: Backlog
A35: 4.5 | B35: Results | C35: Dàlia | D35: 46315 | E35: 46317 | H35: =NETWORKDAYS(D35,E35,Holidays!$A$2:$A$1000) | I35: Backlog
A36: 4.6 | B36: Discussion | C36: Adriana | D36: 46315 | E36: 46317 | H36: =NETWORKDAYS(D36,E36,Holidays!$A$2:$A$1000) | I36: Backlog
A37: 4.7 | B37: Abstract and author contributions | C37: Elsa | D37: 46317 | E37: 46318 | H37: =NETWORKDAYS(D37,E37,Holidays!$A$2:$A$1000) | I37: Backlog
A38: 4.8 | B38: Joint review | C38: All | D38: 46318 | E38: 46318 | H38: =NETWORKDAYS(D38,E38,Holidays!$A$2:$A$1000) | I38: Backlog
A39: 4.9 | B39: Submission on Moodle | C39: Adriana | D39: 46321 | E39: 46321 | H39: =NETWORKDAYS(D39,E39,Holidays!$A$2:$A$1000) | I39: Backlog
A40: WP5 | B40: Defense | D40: 46322 | E40: 46331 | H40: =NETWORKDAYS(D40,E40,Holidays!$A$2:$A$1000)
A41: 5.1 | B41: Slides | C41: All | D41: 46322 | E41: 46324 | H41: =NETWORKDAYS(D41,E41,Holidays!$A$2:$A$1000) | I41: Backlog
A42: 5.2 | B42: Formatting presentation | C42: Elsa | D42: 46325 | E42: 46325 | H42: =NETWORKDAYS(D42,E42,Holidays!$A$2:$A$1000) | I42: Backlog
...

Sheet Holidays
A1: Holiday date
A2: 46276
A3: 46289
A4: 46307
A5: 46364
